<?xml version="1.0"?>
<robot xmlns:xacro="http://www.ros.org/wiki/xacro">
<xacro:include filename="$(find boat_description)/urdf/common_inertia.xacro"/>
    <xacro:macro name="wheel_xacro" params="wheel_name xyz">
        <!-- Second part of the robot: IMU -->
        <link name="${wheel_name}_link">
            <!-- visual of parts -->
            <visual>
                <!-- offset and rotation relative to self center -->
                <origin xyz="0.0 0.0 0.0" rpy="1.57079 0.0 0.0"/>
                <!-- geometry description -->
                <geometry>
                    <cylinder radius="0.032" length="0.04"/>
                </geometry>
                <!-- Material description -->
                <material name="yellow">
                    <color rgba="1.0 1.0 0.0 0.8"/>
                </material>
            </visual>
            <collision>
                <!-- offset and rotation relative to self center -->
                <origin xyz="0.0 0.0 0.0" rpy="1.57079 0.0 0.0"/>
                <!-- geometry description -->
                <geometry>
                    <cylinder radius="0.032" length="0.04"/>
                </geometry>
                <!-- Material description -->
                <material name="white">
                    <color rgba="1.0 1.0 1.0 0.8"/>
                </material>
            </collision>
            <xacro:cylinder_inertia m="0.05" r="0.032" h="0.04"/>
        </link>

        <!-- Joint to connect parts -->
        <!-- Type is either fixed or revolute-->
        <joint name="${wheel_name}_joint" type="continuous">
            <origin xyz="${xyz}" rpy="0.0 0.0 0.0"/>
            <parent link="base_link"/>
            <child link="${wheel_name}_link"/>
            <axis xyz="0.0 1.0 0.0"/>
        </joint>

        <gazebo reference="${wheel_name}_link">
            <mu1 value="20.0"/>
            <mu2 value="20.0"/>
            <kp value="1000000000.0"/>
            <kd value="1.0"/>
        </gazebo>
    </xacro:macro>
</robot>
